[2022-10-28T22:27:37.090+0000] {taskinstance.py:1165} INFO - Dependencies all met for <TaskInstance: ENG_hourly_process_v1.calculate_hourly_demand_forecast scheduled__2022-10-26T04:05:00+00:00 [queued]>
[2022-10-28T22:27:37.200+0000] {taskinstance.py:1165} INFO - Dependencies all met for <TaskInstance: ENG_hourly_process_v1.calculate_hourly_demand_forecast scheduled__2022-10-26T04:05:00+00:00 [queued]>
[2022-10-28T22:27:37.201+0000] {taskinstance.py:1362} INFO - 
--------------------------------------------------------------------------------
[2022-10-28T22:27:37.228+0000] {taskinstance.py:1363} INFO - Starting attempt 1 of 2
[2022-10-28T22:27:37.229+0000] {taskinstance.py:1364} INFO - 
--------------------------------------------------------------------------------
[2022-10-28T22:27:38.024+0000] {taskinstance.py:1383} INFO - Executing <Task(PythonOperator): calculate_hourly_demand_forecast> on 2022-10-26 04:05:00+00:00
[2022-10-28T22:27:38.065+0000] {standard_task_runner.py:55} INFO - Started process 740 to run task
[2022-10-28T22:27:38.081+0000] {standard_task_runner.py:82} INFO - Running: ['***', 'tasks', 'run', 'ENG_hourly_process_v1', 'calculate_hourly_demand_forecast', 'scheduled__2022-10-26T04:05:00+00:00', '--job-id', '5', '--raw', '--subdir', 'DAGS_FOLDER/ENG_hourly_process_dag.py', '--cfg-path', '/tmp/tmp141l74vd']
[2022-10-28T22:27:38.085+0000] {standard_task_runner.py:83} INFO - Job 5: Subtask calculate_hourly_demand_forecast
[2022-10-28T22:27:38.358+0000] {task_command.py:376} INFO - Running <TaskInstance: ENG_hourly_process_v1.calculate_hourly_demand_forecast scheduled__2022-10-26T04:05:00+00:00 [running]> on host 74ce152bc4b9
[2022-10-28T22:27:38.943+0000] {taskinstance.py:1592} INFO - Exporting the following env vars:
AIRFLOW_CTX_DAG_EMAIL=colmo786@gmail.com
AIRFLOW_CTX_DAG_OWNER=energy
AIRFLOW_CTX_DAG_ID=ENG_hourly_process_v1
AIRFLOW_CTX_TASK_ID=calculate_hourly_demand_forecast
AIRFLOW_CTX_EXECUTION_DATE=2022-10-26T04:05:00+00:00
AIRFLOW_CTX_TRY_NUMBER=1
AIRFLOW_CTX_DAG_RUN_ID=scheduled__2022-10-26T04:05:00+00:00
[2022-10-28T22:27:38.982+0000] {logging_mixin.py:120} WARNING - /home/***/.local/lib/python3.7/site-packages/***/utils/context.py:297 AirflowContextDeprecationWarning: Accessing 'execution_date' from the template is deprecated and will be removed in a future version. Please use 'data_interval_start' or 'logical_date' instead.
[2022-10-28T22:27:38.983+0000] {logging_mixin.py:120} INFO - INFO calculate_hourly_demand_forecast execution init:  2022-10-26T04:05:00+00:00
[2022-10-28T22:27:38.983+0000] {logging_mixin.py:120} INFO - WORKDIR: /opt/***
[2022-10-28T22:27:39.043+0000] {logging_mixin.py:120} INFO - INFO Module build_postgres_cnxn: DB Connection to host local_pgdb Ok
[2022-10-28T22:27:39.074+0000] {logging_mixin.py:120} INFO - INFO pg_select_to_pandas: query executed Ok. Number of records returned: 1
[2022-10-28T22:27:39.091+0000] {logging_mixin.py:120} INFO - INFO pg_select_to_pandas: query executed Ok. Number of records returned: 48
[2022-10-28T22:29:01.370+0000] {logging_mixin.py:120} INFO - 1/1 [==============================] - ETA: 0s
[2022-10-28T22:29:01.371+0000] {logging_mixin.py:120} INFO - 1/1 [==============================] - 73s 73s/step
[2022-10-28T22:29:01.644+0000] {logging_mixin.py:120} INFO - INFO _calculate_hourly_demand_forecast: forecast calculated for next 24 hours. Since: 2022-10-27 00:00
[2022-10-28T22:29:49.132+0000] {logging_mixin.py:120} INFO - ERROR _calculate_hourly_demand_forecast calling submodule: ERROR api_request_to_pandas: Error requesting API: http://nolaborables.com.ar/api/v2/feriados/2022
Traceback (most recent call last):   File "/usr/local/lib/python3.7/urllib/request.py", line 1350, in do_open     encode_chunked=req.has_header('Transfer-encoding'))   File "/usr/local/lib/python3.7/http/client.py", line 1281, in request     self._send_request(method, url, body, headers, encode_chunked)   File "/usr/local/lib/python3.7/http/client.py", line 1327, in _send_request     self.endheaders(body, encode_chunked=encode_chunked)   File "/usr/local/lib/python3.7/http/client.py", line 1276, in endheaders     self._send_output(message_body, encode_chunked=encode_chunked)   File "/usr/local/lib/python3.7/http/client.py", line 1036, in _send_output     self.send(msg)   File "/usr/local/lib/python3.7/http/client.py", line 976, in send     self.connect()   File "/usr/local/lib/python3.7/http/client.py", line 948, in connect     (self.host,self.port), self.timeout, self.source_address)   File "/usr/local/lib/python3.7/socket.py", line 707, in create_connection     for res in getaddrinfo(host, port, 0, SOCK_STREAM):   File "/usr/local/lib/python3.7/socket.py", line 752, in getaddrinfo     for res in _socket.getaddrinfo(host, port, family, type, proto, flags): socket.gaierror: [Errno -3] Temporary failure in name resolution  During handling of the above exception, another exception occurred:  Traceback (most recent call last):   File "/opt/***/dags/energy.py", line 111, in _url_request_to_pandas     response = urllib.request.urlopen(_request)   File "/usr/local/lib/python3.7/urllib/request.py", line 222, in urlopen     return opener.open(url, data, timeout)   File "/usr/local/lib/python3.7/urllib/request.py", line 525, in open     response = self._open(req, data)   File "/usr/local/lib/python3.7/urllib/request.py", line 543, in _open     '_open', req)   File "/usr/local/lib/python3.7/urllib/request.py", line 503, in _call_chain     result = func(*args)   File "/usr/local/lib/python3.7/urllib/request.py", line 1378, in http_open     return self.do_open(http.client.HTTPConnection, req)   File "/usr/local/lib/python3.7/urllib/request.py", line 1352, in do_open     raise URLError(err) urllib.error.URLError: <urlopen error [Errno -3] Temporary failure in name resolution>
[2022-10-28T22:29:49.147+0000] {logging_mixin.py:120} INFO - ERROR calculate_hourly_demand_forecast. ERROR api_request_to_pandas: Error requesting API: http://nolaborables.com.ar/api/v2/feriados/2022
Traceback (most recent call last):   File "/usr/local/lib/python3.7/urllib/request.py", line 1350, in do_open     encode_chunked=req.has_header('Transfer-encoding'))   File "/usr/local/lib/python3.7/http/client.py", line 1281, in request     self._send_request(method, url, body, headers, encode_chunked)   File "/usr/local/lib/python3.7/http/client.py", line 1327, in _send_request     self.endheaders(body, encode_chunked=encode_chunked)   File "/usr/local/lib/python3.7/http/client.py", line 1276, in endheaders     self._send_output(message_body, encode_chunked=encode_chunked)   File "/usr/local/lib/python3.7/http/client.py", line 1036, in _send_output     self.send(msg)   File "/usr/local/lib/python3.7/http/client.py", line 976, in send     self.connect()   File "/usr/local/lib/python3.7/http/client.py", line 948, in connect     (self.host,self.port), self.timeout, self.source_address)   File "/usr/local/lib/python3.7/socket.py", line 707, in create_connection     for res in getaddrinfo(host, port, 0, SOCK_STREAM):   File "/usr/local/lib/python3.7/socket.py", line 752, in getaddrinfo     for res in _socket.getaddrinfo(host, port, family, type, proto, flags): socket.gaierror: [Errno -3] Temporary failure in name resolution  During handling of the above exception, another exception occurred:  Traceback (most recent call last):   File "/opt/***/dags/energy.py", line 111, in _url_request_to_pandas     response = urllib.request.urlopen(_request)   File "/usr/local/lib/python3.7/urllib/request.py", line 222, in urlopen     return opener.open(url, data, timeout)   File "/usr/local/lib/python3.7/urllib/request.py", line 525, in open     response = self._open(req, data)   File "/usr/local/lib/python3.7/urllib/request.py", line 543, in _open     '_open', req)   File "/usr/local/lib/python3.7/urllib/request.py", line 503, in _call_chain     result = func(*args)   File "/usr/local/lib/python3.7/urllib/request.py", line 1378, in http_open     return self.do_open(http.client.HTTPConnection, req)   File "/usr/local/lib/python3.7/urllib/request.py", line 1352, in do_open     raise URLError(err) urllib.error.URLError: <urlopen error [Errno -3] Temporary failure in name resolution>
[2022-10-28T22:29:49.148+0000] {taskinstance.py:1851} ERROR - Task failed with exception
Traceback (most recent call last):
  File "/home/airflow/.local/lib/python3.7/site-packages/airflow/operators/python.py", line 175, in execute
    return_value = self.execute_callable()
  File "/home/airflow/.local/lib/python3.7/site-packages/airflow/operators/python.py", line 193, in execute_callable
    return self.python_callable(*self.op_args, **self.op_kwargs)
  File "/opt/airflow/dags/ENG_hourly_process_dag.py", line 66, in calculate_hourly_demand_forecast
    raise ValueError()
ValueError
[2022-10-28T22:29:48.700+0000] {taskinstance.py:1406} INFO - Marking task as UP_FOR_RETRY. dag_id=ENG_hourly_process_v1, task_id=calculate_hourly_demand_forecast, execution_date=20221026T040500, start_date=20221028T222737, end_date=20221028T222948
[2022-10-28T22:29:48.880+0000] {standard_task_runner.py:105} ERROR - Failed to execute job 5 for task calculate_hourly_demand_forecast (; 740)
[2022-10-28T22:29:49.000+0000] {local_task_job.py:164} INFO - Task exited with return code 1
[2022-10-28T22:29:49.109+0000] {local_task_job.py:273} INFO - 0 downstream tasks scheduled from follow-on schedule check
[2022-10-29T00:34:00.874+0000] {taskinstance.py:1165} INFO - Dependencies all met for <TaskInstance: ENG_hourly_process_v1.calculate_hourly_demand_forecast scheduled__2022-10-26T04:05:00+00:00 [queued]>
[2022-10-29T00:34:01.159+0000] {taskinstance.py:1165} INFO - Dependencies all met for <TaskInstance: ENG_hourly_process_v1.calculate_hourly_demand_forecast scheduled__2022-10-26T04:05:00+00:00 [queued]>
[2022-10-29T00:34:01.159+0000] {taskinstance.py:1362} INFO - 
--------------------------------------------------------------------------------
[2022-10-29T00:34:01.160+0000] {taskinstance.py:1363} INFO - Starting attempt 1 of 2
[2022-10-29T00:34:01.160+0000] {taskinstance.py:1364} INFO - 
--------------------------------------------------------------------------------
[2022-10-29T00:34:01.488+0000] {taskinstance.py:1383} INFO - Executing <Task(PythonOperator): calculate_hourly_demand_forecast> on 2022-10-26 04:05:00+00:00
[2022-10-29T00:34:02.422+0000] {standard_task_runner.py:55} INFO - Started process 370 to run task
[2022-10-29T00:34:02.488+0000] {standard_task_runner.py:82} INFO - Running: ['***', 'tasks', 'run', 'ENG_hourly_process_v1', 'calculate_hourly_demand_forecast', 'scheduled__2022-10-26T04:05:00+00:00', '--job-id', '17', '--raw', '--subdir', 'DAGS_FOLDER/ENG_hourly_process_dag.py', '--cfg-path', '/tmp/tmpu21v442s']
[2022-10-29T00:34:02.631+0000] {standard_task_runner.py:83} INFO - Job 17: Subtask calculate_hourly_demand_forecast
[2022-10-29T00:34:03.581+0000] {task_command.py:376} INFO - Running <TaskInstance: ENG_hourly_process_v1.calculate_hourly_demand_forecast scheduled__2022-10-26T04:05:00+00:00 [running]> on host 6800cd8e39a3
[2022-10-29T00:34:04.643+0000] {taskinstance.py:1592} INFO - Exporting the following env vars:
AIRFLOW_CTX_DAG_EMAIL=colmo786@gmail.com
AIRFLOW_CTX_DAG_OWNER=energy
AIRFLOW_CTX_DAG_ID=ENG_hourly_process_v1
AIRFLOW_CTX_TASK_ID=calculate_hourly_demand_forecast
AIRFLOW_CTX_EXECUTION_DATE=2022-10-26T04:05:00+00:00
AIRFLOW_CTX_TRY_NUMBER=1
AIRFLOW_CTX_DAG_RUN_ID=scheduled__2022-10-26T04:05:00+00:00
[2022-10-29T00:34:04.682+0000] {logging_mixin.py:120} WARNING - /home/***/.local/lib/python3.7/site-packages/***/utils/context.py:297 AirflowContextDeprecationWarning: Accessing 'execution_date' from the template is deprecated and will be removed in a future version. Please use 'data_interval_start' or 'logical_date' instead.
[2022-10-29T00:34:04.703+0000] {logging_mixin.py:120} INFO - INFO calculate_hourly_demand_forecast execution init:  2022-10-26T04:05:00+00:00
[2022-10-29T00:34:04.715+0000] {logging_mixin.py:120} INFO - WORKDIR: /opt/***
[2022-10-29T00:34:04.782+0000] {logging_mixin.py:120} INFO - INFO Module build_postgres_cnxn: DB Connection to host local_pgdb Ok
[2022-10-29T00:34:04.814+0000] {logging_mixin.py:120} INFO - INFO pg_select_to_pandas: query executed Ok. Number of records returned: 1
[2022-10-29T00:34:04.832+0000] {logging_mixin.py:120} INFO - INFO pg_select_to_pandas: query executed Ok. Number of records returned: 48
[2022-10-29T00:34:42.735+0000] {logging_mixin.py:120} INFO - 1/1 [==============================] - ETA: 0s
[2022-10-29T00:34:42.736+0000] {logging_mixin.py:120} INFO - 1/1 [==============================] - 14s 14s/step
[2022-10-29T00:34:43.016+0000] {logging_mixin.py:120} INFO - INFO _calculate_hourly_demand_forecast: forecast calculated for next 24 hours. Since: 2022-10-27 00:00
[2022-10-29T00:34:57.136+0000] {logging_mixin.py:120} INFO - INFO _calculate_hourly_demand_forecast - 24 records were upserted. Table cammesa_db.hourly_demand_forecast.
[2022-10-29T00:34:57.139+0000] {python.py:177} INFO - Done. Returned value was: None
[2022-10-29T00:34:57.389+0000] {taskinstance.py:1406} INFO - Marking task as SUCCESS. dag_id=ENG_hourly_process_v1, task_id=calculate_hourly_demand_forecast, execution_date=20221026T040500, start_date=20221029T003400, end_date=20221029T003457
[2022-10-29T00:34:57.665+0000] {local_task_job.py:164} INFO - Task exited with return code 0
[2022-10-29T00:34:57.749+0000] {local_task_job.py:273} INFO - 0 downstream tasks scheduled from follow-on schedule check
